
  You can now view your Streamlit app in your browser.

  Local URL: http://localhost:8501
  Network URL: http://192.168.100.40:8501

2025-07-07 16:31:13.901 Received event for non-watched file: /home/abelxiaoxing/work/PatentAgent/main.py
2025-07-07 17:08:28.445 Uncaught app execution
Traceback (most recent call last):
  File "/home/abelxiaoxing/work/PatentAgent/.venv/lib/python3.12/site-packages/streamlit/runtime/scriptrunner/exec_code.py", line 121, in exec_func_with_error_handling
    result = func()
             ^^^^^^
  File "/home/abelxiaoxing/work/PatentAgent/.venv/lib/python3.12/site-packages/streamlit/runtime/scriptrunner/script_runner.py", line 645, in code_to_exec
    exec(code, module.__dict__)
  File "/home/abelxiaoxing/work/PatentAgent/main.py", line 287, in <module>
    main()
  File "/home/abelxiaoxing/work/PatentAgent/main.py", line 26, in main
    st.session_state.llm_client = LLMClient(st.session_state.config)
                                  ^^^^^^^^^^^^^^^^^^^^^^^^^^^^^^^^^^
  File "/home/abelxiaoxing/work/PatentAgent/llm_client.py", line 29, in __init__
    genai.configure(api_key=api_key)
    ^^^^^^^^^^^^^^^
AttributeError: module 'google.genai' has no attribute 'configure'
2025-07-07 17:09:00.701 Uncaught app execution
Traceback (most recent call last):
  File "/home/abelxiaoxing/work/PatentAgent/.venv/lib/python3.12/site-packages/streamlit/runtime/scriptrunner/exec_code.py", line 121, in exec_func_with_error_handling
    result = func()
             ^^^^^^
  File "/home/abelxiaoxing/work/PatentAgent/.venv/lib/python3.12/site-packages/streamlit/runtime/scriptrunner/script_runner.py", line 645, in code_to_exec
    exec(code, module.__dict__)
  File "/home/abelxiaoxing/work/PatentAgent/main.py", line 287, in <module>
    main()
  File "/home/abelxiaoxing/work/PatentAgent/main.py", line 26, in main
    st.session_state.llm_client = LLMClient(st.session_state.config)
                                  ^^^^^^^^^^^^^^^^^^^^^^^^^^^^^^^^^^
  File "/home/abelxiaoxing/work/PatentAgent/llm_client.py", line 29, in __init__
    genai.configure(api_key=api_key)
    ^^^^^^^^^^^^^^^
AttributeError: module 'google.genai' has no attribute 'configure'
2025-07-07 17:09:02.808 Uncaught app execution
Traceback (most recent call last):
  File "/home/abelxiaoxing/work/PatentAgent/.venv/lib/python3.12/site-packages/streamlit/runtime/scriptrunner/exec_code.py", line 121, in exec_func_with_error_handling
    result = func()
             ^^^^^^
  File "/home/abelxiaoxing/work/PatentAgent/.venv/lib/python3.12/site-packages/streamlit/runtime/scriptrunner/script_runner.py", line 645, in code_to_exec
    exec(code, module.__dict__)
  File "/home/abelxiaoxing/work/PatentAgent/main.py", line 287, in <module>
    main()
  File "/home/abelxiaoxing/work/PatentAgent/main.py", line 26, in main
    st.session_state.llm_client = LLMClient(st.session_state.config)
                                  ^^^^^^^^^^^^^^^^^^^^^^^^^^^^^^^^^^
  File "/home/abelxiaoxing/work/PatentAgent/llm_client.py", line 29, in __init__
    genai.configure(api_key=api_key)
    ^^^^^^^^^^^^^^^
AttributeError: module 'google.genai' has no attribute 'configure'
2025-07-07 17:10:26.009 Uncaught app execution
Traceback (most recent call last):
  File "/home/abelxiaoxing/work/PatentAgent/.venv/lib/python3.12/site-packages/streamlit/runtime/scriptrunner/exec_code.py", line 121, in exec_func_with_error_handling
    result = func()
             ^^^^^^
  File "/home/abelxiaoxing/work/PatentAgent/.venv/lib/python3.12/site-packages/streamlit/runtime/scriptrunner/script_runner.py", line 645, in code_to_exec
    exec(code, module.__dict__)
  File "/home/abelxiaoxing/work/PatentAgent/main.py", line 287, in <module>
    main()
  File "/home/abelxiaoxing/work/PatentAgent/main.py", line 26, in main
    st.session_state.llm_client = LLMClient(st.session_state.config)
                                  ^^^^^^^^^^^^^^^^^^^^^^^^^^^^^^^^^^
  File "/home/abelxiaoxing/work/PatentAgent/llm_client.py", line 32, in __init__
    self.client = genai.GenerativeModel(self.model, api_key=api_key)
                  ^^^^^^^^^^^^^^^^^^^^^
AttributeError: module 'google.genai' has no attribute 'GenerativeModel'
2025-07-07 17:10:29.070 Uncaught app execution
Traceback (most recent call last):
  File "/home/abelxiaoxing/work/PatentAgent/.venv/lib/python3.12/site-packages/streamlit/runtime/scriptrunner/exec_code.py", line 121, in exec_func_with_error_handling
    result = func()
             ^^^^^^
  File "/home/abelxiaoxing/work/PatentAgent/.venv/lib/python3.12/site-packages/streamlit/runtime/scriptrunner/script_runner.py", line 645, in code_to_exec
    exec(code, module.__dict__)
  File "/home/abelxiaoxing/work/PatentAgent/main.py", line 287, in <module>
    main()
  File "/home/abelxiaoxing/work/PatentAgent/main.py", line 26, in main
    st.session_state.llm_client = LLMClient(st.session_state.config)
                                  ^^^^^^^^^^^^^^^^^^^^^^^^^^^^^^^^^^
  File "/home/abelxiaoxing/work/PatentAgent/llm_client.py", line 32, in __init__
    self.client = genai.GenerativeModel(self.model, api_key=api_key)
                  ^^^^^^^^^^^^^^^^^^^^^
AttributeError: module 'google.genai' has no attribute 'GenerativeModel'
2025-07-07 17:22:58.544 Script compilation error
Traceback (most recent call last):
  File "/home/abelxiaoxing/work/PatentAgent/.venv/lib/python3.12/site-packages/streamlit/runtime/scriptrunner/script_runner.py", line 553, in _run_script
    code = self._script_cache.get_bytecode(script_path)
           ^^^^^^^^^^^^^^^^^^^^^^^^^^^^^^^^^^^^^^^^^^^^
  File "/home/abelxiaoxing/work/PatentAgent/.venv/lib/python3.12/site-packages/streamlit/runtime/scriptrunner/script_cache.py", line 72, in get_bytecode
    filebody = magic.add_magic(filebody, script_path)
               ^^^^^^^^^^^^^^^^^^^^^^^^^^^^^^^^^^^^^^
  File "/home/abelxiaoxing/work/PatentAgent/.venv/lib/python3.12/site-packages/streamlit/runtime/scriptrunner/magic.py", line 46, in add_magic
    tree = ast.parse(code, script_path, "exec")
           ^^^^^^^^^^^^^^^^^^^^^^^^^^^^^^^^^^^^
  File "/usr/lib/python3.12/ast.py", line 52, in parse
    return compile(source, filename, mode, flags,
           ^^^^^^^^^^^^^^^^^^^^^^^^^^^^^^^^^^^^^^
  File "/home/abelxiaoxing/work/PatentAgent/main.py", line 19
    from workflows (
                   ^
SyntaxError: invalid syntax
2025-07-07 17:22:58.623 Thread 'MainThread': missing ScriptRunContext! This warning can be ignored when running in bare mode.
2025-07-07 17:23:10.154 Script compilation error
Traceback (most recent call last):
  File "/home/abelxiaoxing/work/PatentAgent/.venv/lib/python3.12/site-packages/streamlit/runtime/scriptrunner/script_runner.py", line 553, in _run_script
    code = self._script_cache.get_bytecode(script_path)
           ^^^^^^^^^^^^^^^^^^^^^^^^^^^^^^^^^^^^^^^^^^^^
  File "/home/abelxiaoxing/work/PatentAgent/.venv/lib/python3.12/site-packages/streamlit/runtime/scriptrunner/script_cache.py", line 72, in get_bytecode
    filebody = magic.add_magic(filebody, script_path)
               ^^^^^^^^^^^^^^^^^^^^^^^^^^^^^^^^^^^^^^
  File "/home/abelxiaoxing/work/PatentAgent/.venv/lib/python3.12/site-packages/streamlit/runtime/scriptrunner/magic.py", line 46, in add_magic
    tree = ast.parse(code, script_path, "exec")
           ^^^^^^^^^^^^^^^^^^^^^^^^^^^^^^^^^^^^
  File "/usr/lib/python3.12/ast.py", line 52, in parse
    return compile(source, filename, mode, flags,
           ^^^^^^^^^^^^^^^^^^^^^^^^^^^^^^^^^^^^^^
  File "/home/abelxiaoxing/work/PatentAgent/main.py", line 19
    from workflows (
                   ^
SyntaxError: invalid syntax
2025-07-07 17:23:10.157 Thread 'MainThread': missing ScriptRunContext! This warning can be ignored when running in bare mode.
2025-07-07 17:23:35.423 Uncaught app execution
Traceback (most recent call last):
  File "/home/abelxiaoxing/work/PatentAgent/.venv/lib/python3.12/site-packages/streamlit/runtime/scriptrunner/exec_code.py", line 121, in exec_func_with_error_handling
    result = func()
             ^^^^^^
  File "/home/abelxiaoxing/work/PatentAgent/.venv/lib/python3.12/site-packages/streamlit/runtime/scriptrunner/script_runner.py", line 645, in code_to_exec
    exec(code, module.__dict__)
  File "/home/abelxiaoxing/work/PatentAgent/main.py", line 301, in <module>
    main()
  File "/home/abelxiaoxing/work/PatentAgent/main.py", line 41, in main
    st.session_state.llm_client = LLMClient(st.session_state.config)
                                  ^^^^^^^^^^^^^^^^^^^^^^^^^^^^^^^^^^
  File "/home/abelxiaoxing/work/PatentAgent/llm_client.py", line 32, in __init__
    self.client = genai.GenerativeModel(self.model, api_key=api_key)
                  ^^^^^^^^^^^^^^^^^^^^^
AttributeError: module 'google.genai' has no attribute 'GenerativeModel'
